<?xml version="1.0" ?>
<robot name="mobile_manipulator2_description">
  <!-- Dummy root link to avoid KDL inertia warning -->
  <link name="world"/>
  
  <joint name="world_to_base" type="fixed">
    <origin xyz="0 0 0" rpy="0 0 0"/>
    <parent link="world"/>
    <child link="base_link"/>
  </joint>
  
  <link name="base_link">
    <inertial>
      <origin rpy="0 0 0" xyz="-0.0312209606413168 -1.37168643094102E-05 -0.0624311561488474"/>
      <mass value="3.66600808570302"/>
      <inertia ixx="0.070830972506108" ixy="0.000423733904503755" ixz="-0.0004402307499561" iyy="0.0538747474413543" iyz="0.000250637811260168" izz="0.118808674602765"/>
    </inertial>
    <visual>
      <origin rpy="0 0 0" xyz="0 0 0"/>
      <geometry>
        <mesh filename="package://mobile_manipulator2_description/meshes/base_link.STL"/>
      </geometry>
      <material name="">
        <color rgba="1 1 1 1"/>
      </material>
    </visual>
    <collision>
      <origin rpy="0 0 0" xyz="0 0 0"/>
      <geometry>
        <mesh filename="package://mobile_manipulator2_description/meshes/collision/base_link_collision.STL"/>
      </geometry>
    </collision>
  </link>
  <link name="box_Link">
    <inertial>
      <origin rpy="0 0 0" xyz="-0.0336792278049677 -0.00458080590131121 0.046046222818299"/>
      <mass value="1.96086062558564"/>
      <inertia ixx="0.00861532872920901" ixy="-0.000126429659448238" ixz="-4.57098901476866E-05" iyy="0.0243467421162108" iyz="-2.86453497285015E-05" izz="0.0322309365376531"/>
    </inertial>
    <visual>
      <origin rpy="0 0 0" xyz="0 0 0"/>
      <geometry>
        <mesh filename="package://mobile_manipulator2_description/meshes/box_Link.STL"/>
      </geometry>
      <material name="">
        <color rgba="1 1 1 1"/>
      </material>
    </visual>
    <collision>
      <origin rpy="0 0 0" xyz="0 0 0"/>
      <geometry>
        <mesh filename="package://mobile_manipulator2_description/meshes/collision/box_Link_collision.STL"/>
      </geometry>
    </collision>
  </link>
  <joint name="box_joint" type="fixed">
    <origin rpy="0 0 0" xyz="0 0 0"/>
    <parent link="base_link"/>
    <child link="box_Link"/>
    <axis xyz="0 0 0"/>
  </joint>
  <link name="lifting_Link">
    <inertial>
      <origin rpy="0 0 0" xyz="-0.0645758262218638 3.1034672673273E-05 0.590832686497018"/>
      <mass value="1.28345031134681"/>
      <inertia ixx="0.0137761443631695" ixy="-2.91078208048479E-07" ixz="-0.000720021739199037" iyy="0.00882953168919407" iyz="7.87382666162099E-08" izz="0.00591609424737705"/>
    </inertial>
    <visual>
      <origin rpy="0 0 0" xyz="0 0 0"/>
      <geometry>
        <mesh filename="package://mobile_manipulator2_description/meshes/lifting_Link.STL"/>
      </geometry>
      <material name="">
        <color rgba="0.792156862745098 0.819607843137255 0.933333333333333 1"/>
      </material>
    </visual>
    <collision>
      <origin rpy="0 0 0" xyz="0 0 0"/>
      <geometry>
        <mesh filename="package://mobile_manipulator2_description/meshes/collision/lifting_Link_collision.STL"/>
      </geometry>
    </collision>
  </link>
  <joint name="lifting_joint" type="fixed">
    <origin rpy="0 0 0" xyz="-0.24269 0 0.022"/>
    <parent link="box_Link"/>
    <child link="lifting_Link"/>
    <axis xyz="0 0 0"/>
  </joint>
  <link name="top_camera_Link">
    <inertial>
      <origin rpy="0 0 0" xyz="0.0081944 0.00022525 0.00024018"/>
      <mass value="0.028999"/>
      <inertia ixx="3.8589E-05" ixy="-1.3619E-08" ixz="-2.6151E-08" iyy="3.7635E-06" iyz="2.7688E-08" izz="3.7044E-05"/>
    </inertial>
    <visual>
      <origin rpy="0 0 0" xyz="0 0 0"/>
      <geometry>
        <mesh filename="package://mobile_manipulator2_description/meshes/top_camera_Link.STL"/>
      </geometry>
      <material name="">
        <color rgba="1 1 1 1"/>
      </material>
    </visual>
    <collision>
      <origin rpy="0 0 0" xyz="0 0 0"/>
      <geometry>
        <mesh filename="package://mobile_manipulator2_description/meshes/collision/top_camera_Link_collision.STL"/>
      </geometry>
    </collision>
  </link>
  <joint name="top_camera_joint" type="fixed">
    <origin rpy="0 0 0" xyz="0.056999999999981 0 0.569500339851353"/>
    <parent link="lifting_Link"/>
    <child link="top_camera_Link"/>
    <axis xyz="0 0 0"/>
  </joint>
  <link name="lidar_Link">
    <inertial>
      <origin rpy="0 0 0" xyz="-0.010562 -0.00043095 0.033917"/>
      <mass value="0.11388"/>
      <inertia ixx="0.0001253" ixy="1.1158E-07" ixz="3.3459E-07" iyy="0.00012408" iyz="-2.6657E-08" izz="0.00019563"/>
    </inertial>
    <visual>
      <origin rpy="0 0 0" xyz="0 0 0"/>
      <geometry>
        <mesh filename="package://mobile_manipulator2_description/meshes/lidar_Link.STL"/>
      </geometry>
      <material name="">
        <color rgba="0.78824 0.81961 0.92941 1"/>
      </material>
    </visual>
    <collision>
      <origin rpy="0 0 0" xyz="0 0 0"/>
      <geometry>
        <mesh filename="package://mobile_manipulator2_description/meshes/collision/lidar_Link_collision.STL"/>
      </geometry>
    </collision>
  </link>
  <joint name="lidar_joint" type="fixed">
    <origin rpy="0 0 0" xyz="0.27254 0.00035292 0.0315"/>
    <parent link="base_link"/>
    <child link="lidar_Link"/>
    <axis xyz="0 0 0"/>
  </joint>
  <link name="under_camera_Link">
    <inertial>
      <origin rpy="0 0 0" xyz="0.0088456 0.00020043 0.0003575"/>
      <mass value="0.055353"/>
      <inertia ixx="4.2284E-05" ixy="2.4484E-07" ixz="-6.627E-08" iyy="4.8492E-06" iyz="-2.9109E-09" izz="4.2122E-05"/>
    </inertial>
    <visual>
      <origin rpy="0 0 0" xyz="0 0 0"/>
      <geometry>
        <mesh filename="package://mobile_manipulator2_description/meshes/under_camera_Link.STL"/>
      </geometry>
      <material name="">
        <color rgba="1 1 1 1"/>
      </material>
    </visual>
    <collision>
      <origin rpy="0 0 0" xyz="0 0 0"/>
      <geometry>
        <mesh filename="package://mobile_manipulator2_description/meshes/collision/under_camera_Link_collision.STL"/>
      </geometry>
    </collision>
  </link>
  <joint name="under_camera_joint" type="fixed">
    <origin rpy="0 0 0" xyz="0.30 0 0.15"/>
    <!-- origin rpy="0 0 0" xyz="0.35023 0 -0.00085446"/-->
    <parent link="base_link"/>
    <child link="under_camera_Link"/>
    <axis xyz="0 0 0"/>
  </joint>
  <link name="arm_base">
    <inertial>
      <origin rpy="0 0 0" xyz="-0.00979274765955341 1.82905827587138E-06 0.0410100126360189"/>
      <mass value="0.162548567403693"/>
      <inertia ixx="0.000226596924525071" ixy="-7.33972270153965E-08" ixz="2.13249977802622E-06" iyy="0.000269444772561524" iyz="8.15169009611054E-09" izz="0.000222318258878636"/>
    </inertial>
    <visual>
      <origin rpy="0 0 0" xyz="0 0 0"/>
      <geometry>
        <mesh filename="package://piper_description/meshes/dae/base_link.dae"/>
      </geometry>
      <material name="">
        <color rgba="0.792156862745098 0.819607843137255 0.933333333333333 1"/>
      </material>
    </visual>
    <collision>
      <origin rpy="0 0 0" xyz="0 0 0"/>
      <geometry>
        <mesh filename="package://piper_description/meshes/base_link.STL"/>
      </geometry>
    </collision>
  </link>
  <link name="link1">
    <inertial>
      <origin rpy="0 0 0" xyz="0.00131676031927024 0.000310288842008612 -0.00922874512303437"/>
      <mass value="0.0978679932242825"/>
      <inertia ixx="7.76684558296782E-05" ixy="1.09084650459924E-07" ixz="-1.9748053243241E-06" iyy="9.24967780161547E-05" iyz="9.91284646834582E-07" izz="8.24589062407807E-05"/>
    </inertial>
    <visual>
      <origin rpy="0 0 0" xyz="0 0 0"/>
      <geometry>
        <mesh filename="package://piper_description/meshes/dae/link1.dae"/>
      </geometry>
      <material name="">
        <color rgba="0.792156862745098 0.819607843137255 0.933333333333333 1"/>
      </material>
    </visual>
    <collision>
      <origin rpy="0 0 1.5708" xyz="0 0 0"/>
      <geometry>
        <mesh filename="package://piper_description/meshes/link1.STL"/>
      </geometry>
    </collision>
  </link>
  <joint name="joint1" type="revolute">
    <origin rpy="0 0 -1.5708" xyz="0 0 0.123"/>
    <parent link="arm_base"/>
    <child link="link1"/>
    <axis xyz="0 0 1"/>
    <limit effort="100" lower="-2.618" upper="2.618" velocity="3"/>
  </joint>
  <link name="link2">
    <inertial>
      <origin rpy="0 0 0" xyz="0.148793602378802 -0.00242026983944119 0.00175154638467948"/>
      <mass value="0.290888938633388"/>
      <inertia ixx="0.000148959640166183" ixy="-7.37750384371657E-05" ixz="-9.68688405196236E-07" iyy="0.00172800946632652" iyz="-1.09692225564224E-06" izz="0.0017754628344594"/>
    </inertial>
    <visual>
      <origin rpy="0 0 0" xyz="0 0 0"/>
      <geometry>
        <mesh filename="package://piper_description/meshes/dae/link2.dae"/>
      </geometry>
      <material name="">
        <color rgba="0.792156862745098 0.819607843137255 0.933333333333333 1"/>
      </material>
    </visual>
    <collision>
      <origin rpy="0 0 0.1" xyz="0 0 0"/>
      <geometry>
        <mesh filename="package://piper_description/meshes/link2.STL"/>
      </geometry>
    </collision>
  </link>
  <joint name="joint2" type="revolute">
    <origin rpy="1.5708 -0.034907 -1.5708" xyz="0 0 0"/>
    <parent link="link1"/>
    <child link="link2"/>
    <axis xyz="0 0 1"/>
    <limit effort="100" lower="0" upper="3.14" velocity="3"/>
  </joint>
  <link name="link3">
    <inertial>
      <origin rpy="0 0 0" xyz="-0.0996835215213704 0.0349477226691318 0.000508025815507312"/>
      <mass value="0.290847697793211"/>
      <inertia ixx="0.000107879011637167" ixy="2.92669521203626E-05" ixz="6.825922326238E-07" iyy="0.000214751671792086" iyz="-7.78469047878196E-07" izz="0.000241923439340319"/>
    </inertial>
    <visual>
      <origin rpy="0 0 0" xyz="0 0 0"/>
      <geometry>
        <mesh filename="package://piper_description/meshes/dae/link3.dae"/>
      </geometry>
      <material name="">
        <color rgba="0.792156862745098 0.819607843137255 0.933333333333333 1"/>
      </material>
    </visual>
    <collision>
      <origin rpy="0 0 -1.75" xyz="0 0 0"/>
      <geometry>
        <mesh filename="package://piper_description/meshes/link3.STL"/>
      </geometry>
    </collision>
  </link>
  <joint name="joint3" type="revolute">
    <origin rpy="0 0 0.06604341" xyz="0.28358 0.028726 0"/>
    <parent link="link2"/>
    <child link="link3"/>
    <axis xyz="0 0 1"/>
    <limit effort="100" lower="-2.697" upper="0" velocity="3"/>
  </joint>
  <link name="link4">
    <inertial>
      <origin rpy="0 0 0" xyz="0.000276464622387979 -0.00102803669324875 -0.00472830700561663"/>
      <mass value="0.127087348341362"/>
      <inertia ixx="3.82011730423416E-05" ixy="-4.92358350897513E-08" ixz="4.89589432973119E-08" iyy="4.87048555222578E-05" iyz="6.70802942500512E-08" izz="4.10592077565559E-05"/>
    </inertial>
    <visual>
      <origin rpy="0 0 0" xyz="0 0 0"/>
      <geometry>
        <mesh filename="package://piper_description/meshes/dae/link4.dae"/>
      </geometry>
      <material name="">
        <color rgba="0.792156862745098 0.819607843137255 0.933333333333333 1"/>
      </material>
    </visual>
    <collision>
      <origin rpy="0 0 0" xyz="0 0 0"/>
      <geometry>
        <mesh filename="package://piper_description/meshes/link4.STL"/>
      </geometry>
    </collision>
  </link>
  <joint name="joint4" type="revolute">
    <origin rpy="-1.5708 0 1.3826" xyz="-0.24221 0.068514 0"/>
    <parent link="link3"/>
    <child link="link4"/>
    <axis xyz="0 0 1"/>
    <limit effort="100" lower="-1.832" upper="1.832" velocity="3"/>
  </joint>
  <link name="link5">
    <inertial>
      <origin rpy="0 0 0" xyz="8.82262433516967E-05 0.0566829014808256 -0.00196119720482461"/>
      <mass value="0.144711242639457"/>
      <inertia ixx="4.39644313662493E-05" ixy="-3.59259686444846E-08" ixz="-1.89747741386183E-08" iyy="5.63173920951307E-05" iyz="-2.1540716689785E-07" izz="4.88713664675268E-05"/>
    </inertial>
    <visual>
      <origin rpy="0 0 0" xyz="0 0 0"/>
      <geometry>
        <mesh filename="package://piper_description/meshes/dae/link5.dae"/>
      </geometry>
      <material name="">
        <color rgba="0.792156862745098 0.819607843137255 0.933333333333333 1"/>
      </material>
    </visual>
    <collision>
      <origin rpy="0 0 -3.14" xyz="0 0 0"/>
      <geometry>
        <mesh filename="package://piper_description/meshes/link5.STL"/>
      </geometry>
    </collision>
  </link>
  <joint name="joint5" type="revolute">
    <origin rpy="1.5708 0 0" xyz="0 0 0"/>
    <parent link="link4"/>
    <child link="link5"/>
    <axis xyz="0 0 1"/>
    <limit effort="100" lower="-1.22" upper="1.22" velocity="3"/>
  </joint>
  <link name="link6">
    <inertial>
      <origin rpy="0 0 0" xyz="0.00103120214523473 0.0121761387587524 0.0315480874960164"/>
      <mass value="0.195187143240719"/>
      <inertia ixx="6.43790256535539E-05" ixy="-1.2366166157046E-06" ixz="1.97664606328472E-07" iyy="0.000126146396374301" iyz="2.41157078516408E-06" izz="0.000154087076816444"/>
    </inertial>
    <visual>
      <origin rpy="-1.57 0 0" xyz="-0.002 -0.008 0"/>
      <geometry>
        <mesh filename="package://piper_description/meshes/dae/camera_v3.dae"/>
      </geometry>
      <material name="">
        <color rgba="0.792156862745098 0.819607843137255 0.933333333333333 1"/>
      </material>
    </visual>
    <collision>
      <origin rpy="-1.57 0 0" xyz="-0.002 -0.008 0"/>
      <geometry>
        <mesh filename="package://piper_description/meshes/dae/camera_v3.dae"/>
      </geometry>
    </collision>
  </link>
  <joint name="joint6" type="revolute">
    <origin rpy="-1.5708 -1.5708 0" xyz="0 0.091 0.0014165"/>
    <parent link="link5"/>
    <child link="link6"/>
    <axis xyz="0 0 1"/>
    <limit effort="100" lower="-3.14" upper="3.14" velocity="3"/>
  </joint>
  <!-- Gripper base link - fixed between link6 and gripper fingers -->
  <link name="gripper_base">
    <inertial>
      <origin xyz="-0.000183807162235591 8.05033155577911E-05 0.0321436689908876" rpy="0 0 0"/>
      <mass value="0.45"/>
      <inertia ixx="0.00092934" ixy="0.00000034" ixz="-0.00000738" iyy="0.00071447" iyz="0.00000005" izz="0.00039442"/>
    </inertial>
    <visual>
      <origin xyz="0 0 0" rpy="0 0 0"/>
      <geometry>
        <mesh filename="package://piper_description/meshes/gripper_base.STL"/>
      </geometry>
      <material name="">
        <color rgba="0.792156862745098 0.819607843137255 0.933333333333333 1"/>
      </material>
    </visual>
    <collision>
      <origin xyz="0 0 0" rpy="0 0 0"/>
      <geometry>
        <mesh filename="package://piper_description/meshes/gripper_base.STL"/>
      </geometry>
    </collision>
  </link>
  <joint name="joint6_to_gripper_base" type="fixed">
    <origin xyz="0 0 0" rpy="0 0 0"/>
    <parent link="link6"/>
    <child link="gripper_base"/>
  </joint>
  <link name="link7">
    <inertial>
      <origin rpy="0 0 0" xyz="-0.000277778383727112 -0.0467673043650824 -0.00921029491873201"/>
      <mass value="0.02648229234527"/>
      <inertia ixx="9.99787479924589E-06" ixy="-1.57548495096104E-07" ixz="-2.71342775003487E-08" iyy="6.1795212293655E-06" iyz="-1.58939803580081E-06" izz="1.42102717246564E-05"/>
    </inertial>
    <visual>
      <origin rpy="0 0 0" xyz="0 0 0"/>
      <geometry>
        <mesh filename="package://piper_description/meshes/dae/link7.dae"/>
      </geometry>
      <material name="">
        <color rgba="0.792156862745098 0.819607843137255 0.933333333333333 1"/>
      </material>
    </visual>
    <collision>
      <origin rpy="0 3.14 0" xyz="-0.001 0 0.0003"/>
      <geometry>
        <mesh filename="package://piper_description/meshes/link7.STL"/>
      </geometry>
    </collision>
  </link>
  <joint name="joint7" type="prismatic">
    <origin rpy="1.5708 0 1.5708" xyz="0 0 0.13503"/>
    <parent link="gripper_base"/>
    <child link="link7"/>
    <axis xyz="0 0 -1"/>
    <limit effort="10" lower="0" upper="0.05" velocity="1"/>
  </joint>
  <link name="link8">
    <inertial>
      <origin rpy="0 0 0" xyz="0.000277816920932317 0.0467673824063769 -0.00921030054508036"/>
      <mass value="0.0264822021416248"/>
      <inertia ixx="9.99779119357223E-06" ixy="-1.57542283433504E-07" ixz="2.71367446701359E-08" iyy="6.17952441557932E-06" iyz="1.58939319453383E-06" izz="1.4210192754512E-05"/>
    </inertial>
    <visual>
      <origin rpy="0 0 0" xyz="0 0 0"/>
      <geometry>
        <mesh filename="package://piper_description/meshes/dae/link8.dae"/>
      </geometry>
      <material name="">
        <color rgba="0.792156862745098 0.819607843137255 0.933333333333333 1"/>
      </material>
    </visual>
    <collision>
      <origin rpy="3.14 0 0" xyz="-0.001 0 0.0003"/>
      <geometry>
        <mesh filename="package://piper_description/meshes/link8.STL"/>
      </geometry>
    </collision>
  </link>
  <joint name="joint8" type="prismatic">
    <origin rpy="-1.5708 0 1.5708" xyz="0 0 0.13503"/>
    <parent link="gripper_base"/>
    <child link="link8"/>
    <axis xyz="0 0 1"/>
    <limit effort="10" lower="-0.05" upper="0" velocity="1"/>
  </joint>
  <joint name="arm_joint" type="fixed">
    <origin rpy="0.0 0.0 0.0" xyz="0.118 0 0.1"/>
    <parent link="box_Link"/>
    <child link="arm_base"/>
    <axis xyz="0.0 0.0 0.0"/>
    <limit effort="0.0" lower="0.0" upper="0.0" velocity="0.0"/>
  </joint>
</robot>

